<?xml version="1.0" encoding="utf-8" standalone="yes"?><rss version="2.0" xmlns:atom="http://www.w3.org/2005/Atom"><channel><title>PyPlot on KevCaz's Website</title><link>https://kevcaz.github.io/tags/pyplot/</link><description>Recent content in PyPlot on KevCaz's Website</description><generator>Hugo -- gohugo.io</generator><language>en-us</language><copyright>Content under CC0 1.0 Universal unless otherwise specified.</copyright><lastBuildDate>Tue, 23 Nov 2021 00:00:00 +0000</lastBuildDate><atom:link href="https://kevcaz.github.io/tags/pyplot/index.xml" rel="self" type="application/rss+xml"/><item><title>Matplotlib could not be imported by pyimport `[SOLVED]`</title><link>https://kevcaz.github.io/notes/2021/11/2021-11-23_matplotlib_could_not/</link><pubDate>Tue, 23 Nov 2021 00:00:00 +0000</pubDate><guid>https://kevcaz.github.io/notes/2021/11/2021-11-23_matplotlib_could_not/</guid><description>I have been experiencing an issue following a recent Python update. Basically, when I was trying to use PyPlot, I got the following message error.
1 2 3 4 5 6 7 8 9 10 11 12 13 14 15 16 17 18 19 20 21 22 23 24 25 26 27 28 29 30 31 32 33 34 35 36 37 38 39 40 41 42 43 44 45 46 47 48 49 50 51 52 53 54 55 56 julia&amp;gt; using PyPlot ERROR: InitError: PyError (PyImport_ImportModule The Python package matplotlib could not be imported by pyimport.</description></item></channel></rss>